Workbook

Sheet Read Me
A1: Combat Balance Workbook
A2: v0.1 • Draft • единый источник настраиваемых чисел для Combat Lab
A4: Паспорт документа | F4: Контроль качества | K4: Профиль бойцов
A5: Поле | B5: Значение | C5: Статус | D5: Примечание | F5: Метрика | G5: Текущее | H5: Требование | I5: Статус | K5: Параметр | L5: Медведь | M5: Кенгуру | N5: Горилла
A6: Документ | B6: Combat Balance Workbook | C6: Draft | D6: Числовое приложение к CDS v0.1 | F6: Животные | G6: =COUNTA('Fighter Stats'!$A$6:$A$8) -> 3 | H6: 3 | I6: =IF(G6=H6,"OK","ERROR") -> OK | K6: Health | L6: ='Fighter Stats'!D6 -> 1650 | M6: ='Fighter Stats'!D7 -> 1150 | N6: ='Fighter Stats'!D8 -> 1450
A7: Версия | B7: v0.1 | C7: Hypothesis | D7: До пакетных симуляций | F7: Действия | G7: =COUNTA(Actions!$A$6:$A$29) -> 24 | H7: 24 | I7: =IF(G7=H7,"OK","ERROR") -> OK | K7: Power | L7: ='Fighter Stats'!E6 -> 130 | M7: ='Fighter Stats'!E7 -> 100 | N7: ='Fighter Stats'!E8 -> 110
A8: Обновлено | B8: 46232 | C8: Current | D8: Europe/Warsaw | F8: Пассивы | G8: =COUNTA(Passives!$A$6:$A$11) -> 6 | H8: 6 | I8: =IF(G8=H8,"OK","ERROR") -> OK | K8: Armor | L8: ='Fighter Stats'!F6 -> 75 | M8: ='Fighter Stats'!F7 -> 40 | N8: ='Fighter Stats'!F8 -> 95
A9: Владелец | B9: Game Designer / Founder / Product Owner | C9: Assigned | D9: Один владелец решения | F9: Эффекты | G9: =COUNTA(Effects!$A$6:$A$15) -> 10 | H9: 10 | I9: =IF(G9=H9,"OK","ERROR") -> OK | K9: Move Speed | L9: ='Fighter Stats'!K6 -> 70 | M9: ='Fighter Stats'!K7 -> 135 | N9: ='Fighter Stats'!K8 -> 75
A10: Источник правил | B10: Combat Design Specification v0.1 | C10: Linked | D10: Формулы и семантика — в CDS | F10: Тактики | G10: =COUNTA(Tactics!$A$6:$A$9) -> 4 | H10: 4 | I10: =IF(G10=H10,"OK","ERROR") -> OK
A11: Целевой бой | B11: 35–60 секунд | C11: Target | D11: Timeout менее 2% | F11: Экипировка | G11: =COUNTA(Gear!$A$6:$A$14) -> 9 | H11: 9 | I11: =IF(G11=H11,"OK","ERROR") -> OK | K11: JSON map SHA-256: 9b5c4aae4551d2f61ea3d02d4121898e09c0ad333ca4714b112a4124f1e6aebf
A12: JSON schema | B12: combat.balance/0.1 | C12: Mapped | D12: Лист JSON Map | F12: Тестовые сборки | G12: =COUNTA('Test Builds'!$A$6:$A$17) -> 12 | H12: 12 | I12: =IF(G12=H12,"OK","ERROR") -> OK
A13: Числа в коде/CDS | B13: Запрещены | C13: Fixed | D13: Только технические инварианты формата | F13: Matchup rows | G13: =COUNTA('Expected Matchups'!$A$6:$A$14) -> 9 | H13: 9 | I13: =IF(G13=H13,"OK","ERROR") -> OK
F14: Ошибки валидации | G14: =COUNTIF(Validation!$E$6:$E$166,"ERROR") -> 0 | H14: 0 | I14: =IF(G14=H14,"OK","ERROR") -> OK
A16: Как работать с книгой
A17: Шаг | B17: Действие | C17: Результат | D17: Блокирующая проверка
A18: 1 | B18: Менять только жёлтые входные клетки на профильном листе. | C18: Validation пересчитывается. | D18: Нет ERROR.
A19: 2 | B19: Добавить запись в Change Log и повысить ConfigVersion. | C19: Изменение трассируется. | D19: Версия уникальна.
A20: 3 | B20: Экспортировать JSON по живой карте JSON Map. | C20: Сортированный canonical JSON. | D20: ValueType и Required соблюдены.
A21: 4 | B21: Запустить seed sweep и вставить агрегаты в Batch Results. | C21: Получены статистические распределения. | D21: DeterminismFailures = 0.
A22: 5 | B22: Сравнить с Expected Matchups и принять balance pass. | C22: PASS или осознанное изменение гипотезы. | D22: Timeout < 2%; длительность 35–60 s.
A24: Легенда и ключевые ограничения
A25: Цвет | B25: Смысл | C25: Ограничение
A26: Жёлтый | B26: Настраиваемый input | C26: Единственное место изменения числа.
A27: Голубой | B27: Stable ID / ключ | C27: Семантика ID не меняется без новой схемы.
A28: Зелёный | B28: Формула / проверка | C28: Не заменять статическим значением.
A29: Красный | B29: Ошибка | C29: JSON export и batch approval запрещены.

Sheet Global Config
A1: Global Config
A2: Глобальные коэффициенты, пределы, тайминги и ресурсные профили
A3: Жёлтые клетки — настраиваемые данные. Зелёные — вычисляемая проверка диапазона. Любое изменение требует новой ConfigVersion и записи в Change Log.
A5: Key | B5: Group | C5: Description RU | D5: Value | E5: Data Type | F5: Unit | G5: Min | H5: Max | I5: Status | J5: Notes RU | K5: Validation
A6: global.sim.schema_version | B6: Simulation | C6: Версия схемы баланса | D6: combat.balance/0.2 | E6: string | F6: id | I6: Fixed | J6: Менять только вместе со схемой JSON. | K6: =IF(OR(E6="string",E6="bool",AND(D6>=G6,D6<=H6)),"OK","ERROR") -> OK
A7: global.sim.config_version | B7: Simulation | C7: Версия набора параметров | D7: v0.2 | E7: string | F7: id | I7: Hypothesis | J7: Повышается при любом утверждённом balance pass. | K7: =IF(OR(E7="string",E7="bool",AND(D7>=G7,D7<=H7)),"OK","ERROR") -> OK
A8: global.sim.rng_version | B8: Simulation | C8: Версия алгоритма RNG | D8: pcg32/1 | E8: string | F8: id | I8: Hypothesis | J8: Финально фиксируется в Combat Lab Technical Design. | K8: =IF(OR(E8="string",E8="bool",AND(D8>=G8,D8<=H8)),"OK","ERROR") -> OK
A9: global.sim.ordering_version | B9: Simulation | C9: Версия порядка тика | D9: tick-pipeline/1 | E9: string | F9: id | I9: Fixed | J9: Соответствует CDS v0.1, раздел 4.2. | K9: =IF(OR(E9="string",E9="bool",AND(D9>=G9,D9<=H9)),"OK","ERROR") -> OK
A10: global.sim.tick_ms | B10: Simulation | C10: Длительность одного тика | D10: 100 | E10: int | F10: ms | G10: 50 | H10: 200 | I10: Hypothesis | J10: 10 тиков в секунду; все фазы целочисленные. | K10: =IF(OR(E10="string",E10="bool",AND(D10>=G10,D10<=H10)),"OK","ERROR") -> OK
A11: battle.time_limit_ticks | B11: Simulation | C11: Лимит боя | D11: 600 | E11: int | F11: ticks | G11: 350 | H11: 900 | I11: Hypothesis | J11: 60 секунд при tick_ms=100. | K11: =IF(OR(E11="string",E11="bool",AND(D11>=G11,D11<=H11)),"OK","ERROR") -> OK
A12: global.sim.fp_scale | B12: Math | C12: Масштаб fixed-point | D12: 1000 | E12: int | F12: fp | G12: 100 | H12: 100000 | I12: Fixed | J12: 1000 = множитель 1.000 и вероятность 100%. | K12: =IF(OR(E12="string",E12="bool",AND(D12>=G12,D12<=H12)),"OK","ERROR") -> OK
A13: global.sim.probability_min | B13: Math | C13: Минимум вероятности | D13: 0 | E13: fp | F13: fp | G13: 0 | H13: 0 | I13: Fixed | J13: Нижняя граница clamp. | K13: =IF(OR(E13="string",E13="bool",AND(D13>=G13,D13<=H13)),"OK","ERROR") -> OK
A14: global.sim.probability_max | B14: Math | C14: Максимум вероятности | D14: 1000 | E14: fp | F14: fp | G14: 1000 | H14: 1000 | I14: Fixed | J14: Верхняя граница clamp. | K14: =IF(OR(E14="string",E14="bool",AND(D14>=G14,D14<=H14)),"OK","ERROR") -> OK
A15: global.sim.multiplier_min | B15: Math | C15: Минимальный множитель веса | D15: 250 | E15: fp | F15: fp | G15: 0 | H15: 1000 | I15: Hypothesis | J15: 0.250x. | K15: =IF(OR(E15="string",E15="bool",AND(D15>=G15,D15<=H15)),"OK","ERROR") -> OK
A16: global.sim.multiplier_max | B16: Math | C16: Максимальный множитель веса | D16: 3000 | E16: fp | F16: fp | G16: 1000 | H16: 5000 | I16: Hypothesis | J16: 3.000x. | K16: =IF(OR(E16="string",E16="bool",AND(D16>=G16,D16<=H16)),"OK","ERROR") -> OK
A17: global.sim.decision_weight_max | B17: Math | C17: Максимальный итоговый вес | D17: 100000000 | E17: int | F17: weight | G17: 1000000 | H17: 2000000000 | I17: Hypothesis | J17: Ограничивает переполнение суммы весов. | K17: =IF(OR(E17="string",E17="bool",AND(D17>=G17,D17<=H17)),"OK","ERROR") -> OK
A18: global.arena.min_position | B18: Arena | C18: Левая граница арены | D18: 0 | E18: int | F18: position | G18: 0 | H18: 0 | I18: Hypothesis | J18: Закрытый одномерный отрезок. | K18: =IF(OR(E18="string",E18="bool",AND(D18>=G18,D18<=H18)),"OK","ERROR") -> OK
A19: global.arena.max_position | B19: Arena | C19: Правая граница арены | D19: 10000 | E19: int | F19: position | G19: 6000 | H19: 20000 | I19: Hypothesis | J19: Рабочая длина 10 000 условных единиц. | K19: =IF(OR(E19="string",E19="bool",AND(D19>=G19,D19<=H19)),"OK","ERROR") -> OK
A20: global.arena.start_position_a | B20: Arena | C20: Стартовая позиция A | D20: 2000 | E20: int | F20: position | G20: 500 | H20: 4500 | I20: Hypothesis | J20: Зеркальна позиции B. | K20: =IF(OR(E20="string",E20="bool",AND(D20>=G20,D20<=H20)),"OK","ERROR") -> OK
A21: global.arena.start_position_b | B21: Arena | C21: Стартовая позиция B | D21: 8000 | E21: int | F21: position | G21: 5500 | H21: 9500 | I21: Hypothesis | J21: Зеркальна позиции A. | K21: =IF(OR(E21="string",E21="bool",AND(D21>=G21,D21<=H21)),"OK","ERROR") -> OK
... A127: global.control.knockdown_getup_ticks | B127: Control | C127: Knockdown: длительность GetUp | D127: 3 | E127: int | F127: ticks | G127: 1 | H127: 100 | I127: FIXED | J127: OPEN-WP10-20; wakeup in phase 2. | K127: =IF(OR(E127="string",E127="bool",AND(D127>=G127,D127<=H127)),"OK","ERROR") -> OK

Sheet Fighter Stats
A1: Fighter Stats
A2: Характеристики стартовых животных и их уникальные ресурсы
A3: Base Combat Index — только грубая аналитическая средняя рейтингов E:P; он не участвует в боевой формуле. Относительная идентичность комплекта важнее одинаковой суммы.
A5: Animal ID | B5: Display Name RU | C5: Resource ID | D5: Max Health | E5: Power | F5: Armor | G5: Precision | H5: Evasion | I5: Guard | J5: Guard Break | K5: Move Speed | L5: Action Speed | M5: Initiative | N5: Control Power | O5: Control Resistance | P5: Mass | Q5: Max Energy | R5: Energy Regen / tick | S5: Collision Radius | T5: Start Resource | U5: Max Resource | V5: Stagger Threshold | W5: Base Combat Index | X5: Archetype RU | Y5: Win Condition RU | Z5: Status | AA5: Validation
A6: bear | B6: Медведь | C6: rage | D6: 1650 | E6: 130 | F6: 75 | G6: 95 | H6: 55 | I6: 105 | J6: 120 | K6: 70 | L6: 85 | M6: 85 | N6: 125 | O6: 125 | P6: 130 | Q6: 1000 | R6: 12 | S6: 520 | T6: 0 | U6: 1000 | V6: 260 | W6: =ROUND(AVERAGE(E6:P6),0) -> 100 | X6: Танк-комбэкер | Y6: Пережить давление, накопить ярость и наказать длинный commit. | Z6: Hypothesis | AA6: =IF(AND(A6<>"",D6>0,Q6>0,R6>=0,T6>=0,T6<=U6,V6>0),"OK","ERROR") -> OK
A7: kangaroo | B7: Кенгуру | C7: tempo | D7: 1150 | E7: 100 | F7: 40 | G7: 125 | H7: 135 | I7: 65 | J7: 80 | K7: 135 | L7: 125 | M7: 130 | N7: 75 | O7: 70 | P7: 70 | Q7: 1000 | R7: 15 | S7: 430 | T7: 0 | U7: 1000 | V7: 180 | W7: =ROUND(AVERAGE(E7:P7),0) -> 96 | X7: Мобильный темповик | Y7: Держать среднюю дистанцию, чередовать категории и реализовать окно. | Z7: Hypothesis | AA7: =IF(AND(A7<>"",D7>0,Q7>0,R7>=0,T7>=0,T7<=U7,V7>0),"OK","ERROR") -> OK
A8: gorilla | B8: Горилла | C8: grip | D8: 1450 | E8: 110 | F8: 95 | G8: 90 | H8: 45 | I8: 140 | J8: 105 | K8: 75 | L8: 105 | M8: 95 | N8: 145 | O8: 130 | P8: 150 | Q8: 1000 | R8: 11 | S8: 550 | T8: 0 | U8: 1000 | V8: 300 | W8: =ROUND(AVERAGE(E8:P8),0) -> 107 | X8: Контроллер стены | Y8: Загнать к стене, накопить хватку и реализовать grab/control. | Z8: Hypothesis | AA8: =IF(AND(A8<>"",D8>0,Q8>0,R8>=0,T8>=0,T8<=U8,V8>0),"OK","ERROR") -> OK

Sheet Actions
A1: Actions & Abilities
A2: Системные действия, 12 базовых действий и 9 особых приёмов
A3: Урон рассчитывается по CDS; аналитические колонки справа показывают один hit без контекстных множителей. HitSchedule — относительные тики активного окна.
A5: Action ID | B5: Animal ID | C5: Display Name RU | D5: Slot Type | E5: Category | F5: Tags | G5: Base Weight | H5: Preferred Range Min | I5: Preferred Range Max | J5: Hit Range Min | K5: Hit Range Max | L5: Energy Cost | M5: Resource Cost | N5: Base Damage / hit | O5: Power Ratio FP | P5: Min Damage | Q5: Chip Min | R5: Startup Base Ticks | S5: Startup Min Ticks | T5: Startup Max Ticks | U5: Active Ticks | V5: Hit Schedule | W5: Hit Count | X5: Recovery Base Ticks | Y5: Recovery Min Ticks | Z5: Recovery Max Ticks | AA5: Cooldown Ticks | AB5: Action Priority | AC5: Clash Priority | AD5: Grab Priority | AE5: Resolution Priority | AF5: Interrupt Profile | AG5: Blockable | AH5: Dodgeable | AI5: Undodgeable | AJ5: Wall Impact | AK5: Track Target | AL5: Block Base Chance FP | AM5: Block Reduction FP | AN5: Dodge Base Chance FP | AO5: Movement Mode | AP5: Move Distance | AQ5: Base Stagger | AR5: Base Stun Ticks | AS5: Base Knockback | AT5: Knockback Min | AU5: Knockback Max | AV5: Wall Damage / Unit FP | AW5: Wall Damage Min | AX5: Wall Damage Max | AY5: Max Consecutive Uses | AZ5: Opportunity Cap FP | BA5: Hard Opportunity Misses | BB5: Expected Power Term | BC5: Expected vs Benchmark Armor | BD5: Status | BE5: Validation | BF5: Notes RU | BG5: Hit Interrupt Strength | BH5: Hit Interrupt Min Strength | BI5: Hit Interruptible Phases | BJ5: Protected Phases | BK5: Ignored Control Categories
A6: sys_approach | B6: all | C6: Системное сближение | D6: System | E6: Movement | F6: system|movement|approach | G6: 650 | H6: 0 | I6: 1500 | J6: 0 | K6: 0 | L6: 0 | M6: 0 | N6: 0 | O6: 0 | P6: 0 | Q6: 0 | R6: 1 | S6: 1 | T6: 1 | U6: 5 | W6: 0 | X6: 1 | Y6: 1 | Z6: 1 | AA6: 0 | AB6: 5 | AC6: 0 | AD6: 0 | AE6: 5 | AF6: Cancelable | AG6: FALSE | AH6: FALSE | AI6: FALSE | AJ6: FALSE | AK6: TRUE | AL6: 0 | AM6: 0 | AN6: 0 | AO6: Approach | AP6: 0 | AQ6: 0 | AR6: 0 | AS6: 0 | AT6: 0 | AU6: 0 | AV6: 0 | AW6: 0 | AX6: 0 | AY6: 4 | AZ6: 1000 | BA6: 0 | BB6: =IF(B6="all",0,N6+ROUND(VLOOKUP(B6,'Fighter Stats'!$A$6:$E$8,5,FALSE)*O6/'Global Config'!$D$12,0)) -> 0 | BC6: =ROUND(BB6*(1-('Global Config'!$D$36/('Global Config'!$D$36+'Global Config'!$D$23))),0) -> 0 | BD6: Hypothesis | BE6: =IF(AND(A6<>"",H6<=I6,J6<=K6,S6<=R6,R6<=T6,Y6<=X6,X6<=Z6,AT6<=AS6,AS6<=AU6,AW6<=AX6,AY6>=1,L6>=0,M6>=0),"OK","ERROR") -> OK | BF6: Движется к preferred band профиля; дистанция берётся из effective MoveSpeed. | BG6: 0 | BH6: 1 | BI6: Startup|Active
A7: sys_retreat | B7: all | C7: Системное отступление | D7: System | E7: Movement | F7: system|movement|retreat | G7: 450 | H7: 1600 | I7: 3000 | J7: 0 | K7: 0 | L7: 0 | M7: 0 | N7: 0 | O7: 0 | P7: 0 | Q7: 0 | R7: 1 | S7: 1 | T7: 1 | U7: 5 | W7: 0 | X7: 1 | Y7: 1 | Z7: 1 | AA7: 0 | AB7: 5 | AC7: 0 | AD7: 0 | AE7: 5 | AF7: Cancelable | AG7: FALSE | AH7: FALSE | AI7: FALSE | AJ7: FALSE | AK7: TRUE | AL7: 0 | AM7: 0 | AN7: 0 | AO7: Retreat | AP7: 0 | AQ7: 0 | AR7: 0 | AS7: 0 | AT7: 0 | AU7: 0 | AV7: 0 | AW7: 0 | AX7: 0 | AY7: 3 | AZ7: 1000 | BA7: 0 | BB7: =IF(B7="all",0,N7+ROUND(VLOOKUP(B7,'Fighter Stats'!$A$6:$E$8,5,FALSE)*O7/'Global Config'!$D$12,0)) -> 0 | BC7: =ROUND(BB7*(1-('Global Config'!$D$36/('Global Config'!$D$36+'Global Config'!$D$23))),0) -> 0 | BD7: Hypothesis | BE7: =IF(AND(A7<>"",H7<=I7,J7<=K7,S7<=R7,R7<=T7,Y7<=X7,X7<=Z7,AT7<=AS7,AS7<=AU7,AW7<=AX7,AY7>=1,L7>=0,M7>=0),"OK","ERROR") -> OK | BF7: Останавливается у стены; не превращает остаток движения в урон. | BG7: 0 | BH7: 1 | BI7: Startup|Active
A8: sys_wait | B8: all | C8: Системное ожидание | D8: System | E8: Wait | F8: system|wait | G8: 150 | H8: 0 | I8: 10000 | J8: 0 | K8: 0 | L8: 0 | M8: 0 | N8: 0 | O8: 0 | P8: 0 | Q8: 0 | R8: 0 | S8: 0 | T8: 0 | U8: 3 | W8: 0 | X8: 0 | Y8: 0 | Z8: 0 | AA8: 0 | AB8: 1 | AC8: 0 | AD8: 0 | AE8: 1 | AF8: Cancelable | AG8: FALSE | AH8: FALSE | AI8: FALSE | AJ8: FALSE | AK8: FALSE | AL8: 0 | AM8: 0 | AN8: 0 | AO8: None | AP8: 0 | AQ8: 0 | AR8: 0 | AS8: 0 | AT8: 0 | AU8: 0 | AV8: 0 | AW8: 0 | AX8: 0 | AY8: 2 | AZ8: 1000 | BA8: 0 | BB8: =IF(B8="all",0,N8+ROUND(VLOOKUP(B8,'Fighter Stats'!$A$6:$E$8,5,FALSE)*O8/'Global Config'!$D$12,0)) -> 0 | BC8: =ROUND(BB8*(1-('Global Config'!$D$36/('Global Config'!$D$36+'Global Config'!$D$23))),0) -> 0 | BD8: Hypothesis | BE8: =IF(AND(A8<>"",H8<=I8,J8<=K8,S8<=R8,R8<=T8,Y8<=X8,X8<=Z8,AT8<=AS8,AS8<=AU8,AW8<=AX8,AY8>=1,L8>=0,M8>=0),"OK","ERROR") -> OK | BF8: Выбирается при нулевых весах или тактически полезной паузе. | BG8: 0 | BH8: 1 | BI8: Startup
A9: bear_paw_jab | B9: bear | C9: Быстрый удар лапой | D9: Basic | E9: LightStrike | F9: strike|light|fallback | G9: 1000 | H9: 100 | I9: 900 | J9: 0 | K9: 1050 | L9: 0 | M9: 0 | N9: 30 | O9: 450 | P9: 12 | Q9: 4 | R9: 3 | S9: 2 | T9: 5 | U9: 1 | V9: 0 | W9: 1 | X9: 5 | Y9: 3 | Z9: 8 | AA9: 0 | AB9: 20 | AC9: 20 | AD9: 0 | AE9: 20 | AF9: Committed | AG9: TRUE | AH9: TRUE | AI9: FALSE | AJ9: FALSE | AK9: FALSE | AL9: 0 | AM9: 0 | AN9: 0 | AO9: None | AP9: 0 | AQ9: 20 | AR9: 0 | AS9: 0 | AT9: 0 | AU9: 0 | AV9: 0 | AW9: 0 | AX9: 0 | AY9: 2 | AZ9: 1000 | BA9: 0 | BB9: =IF(B9="all",0,N9+ROUND(VLOOKUP(B9,'Fighter Stats'!$A$6:$E$8,5,FALSE)*O9/'Global Config'!$D$12,0)) -> 89 | BC9: =ROUND(BB9*(1-('Global Config'!$D$36/('Global Config'!$D$36+'Global Config'!$D$23))),0) -> 59 | BD9: Hypothesis | BE9: =IF(AND(A9<>"",H9<=I9,J9<=K9,S9<=R9,R9<=T9,Y9<=X9,X9<=Z9,AT9<=AS9,AS9<=AU9,AW9<=AX9,AY9>=1,L9>=0,M9>=0),"OK","ERROR") -> OK | BF9: Безопасный fallback; сильный repeat penalty. | BG9: 1 | BH9: 1 | BI9: Startup
A10: bear_crushing_swipe | B10: bear | C10: Сокрушительный взмах | D10: Basic | E10: HeavyStrike | F10: strike|heavy|guard_break|knockback | G10: 720 | H10: 400 | I10: 1350 | J10: 150 | K10: 1700 | L10: 180 | M10: 0 | N10: 60 | O10: 900 | P10: 25 | Q10: 8 | R10: 8 | S10: 5 | T10: 12 | U10: 2 | V10: 0 | W10: 1 | X10: 12 | Y10: 8 | Z10: 18 | AA10: 35 | AB10: 40 | AC10: 45 | AD10: 0 | AE10: 40 | AF10: Armored | AG10: TRUE | AH10: TRUE | AI10: FALSE | AJ10: FALSE | AK10: FALSE | AL10: 0 | AM10: 0 | AN10: 0 | AO10: Push | AP10: 0 | AQ10: 120 | AR10: 4 | AS10: 650 | AT10: 200 | AU10: 900 | AV10: 0 | AW10: 0 | AX10: 0 | AY10: 1 | AZ10: 1200 | BA10: 0 | BB10: =IF(B10="all",0,N10+ROUND(VLOOKUP(B10,'Fighter Stats'!$A$6:$E$8,5,FALSE)*O10/'Global Config'!$D$12,0)) -> 177 | BC10: =ROUND(BB10*(1-('Global Config'!$D$36/('Global Config'!$D$36+'Global Config'!$D$23))),0) -> 118 | BD10: Hypothesis | BE10: =IF(AND(A10<>"",H10<=I10,J10<=K10,S10<=R10,R10<=T10,Y10<=X10,X10<=Z10,AT10<=AS10,AS10<=AU10,AW10<=AX10,AY10>=1,L10>=0,M10>=0),"OK","ERROR") -> OK | BF10: Наказывает Block/Recovery; длинный telegraph и recovery. | BG10: 3 | BH10: 3 | BI10: Startup | BJ10: Startup|Active
A11: bear_guarded_advance | B11: bear | C11: Защищённое наступление | D11: Basic | E11: BlockMovement | F11: movement|approach|block|defense | G11: 650 | H11: 200 | I11: 900 | J11: 0 | K11: 0 | L11: 100 | M11: 0 | N11: 0 | O11: 0 | P11: 0 | Q11: 0 | R11: 3 | S11: 2 | T11: 5 | U11: 10 | W11: 0 | X11: 6 | Y11: 4 | Z11: 9 | AA11: 20 | AB11: 30 | AC11: 0 | AD11: 0 | AE11: 70 | AF11: Armored | AG11: FALSE | AH11: FALSE | AI11: FALSE | AJ11: FALSE | AK11: TRUE | AL11: 550 | AM11: 500 | AN11: 0 | AO11: Approach | AP11: 700 | AQ11: 0 | AR11: 0 | AS11: 0 | AT11: 0 | AU11: 0 | AV11: 0 | AW11: 0 | AX11: 0 | AY11: 1 | AZ11: 1000 | BA11: 0 | BB11: =IF(B11="all",0,N11+ROUND(VLOOKUP(B11,'Fighter Stats'!$A$6:$E$8,5,FALSE)*O11/'Global Config'!$D$12,0)) -> 0 | BC11: =ROUND(BB11*(1-('Global Config'!$D$36/('Global Config'!$D$36+'Global Config'!$D$23))),0) -> 0 | BD11: Hypothesis | BE11: =IF(AND(A11<>"",H11<=I11,J11<=K11,S11<=R11,R11<=T11,Y11<=X11,X11<=Z11,AT11<=AS11,AS11<=AU11,AW11<=AX11,AY11>=1,L11>=0,M11>=0),"OK","ERROR") -> OK | BF11: Grab проходит через защиту; GuardBreak останавливает движение. | BG11: 0 | BH11: 3 | BI11: Startup|Active | BJ11: Startup|Active
A12: bear_body_check | B12: bear | C12: Таран корпусом | D12: Basic | E12: ApproachStrike | F12: strike|approach|knockback|medium | G12: 700 | H12: 900 | I12: 2100 | J12: 250 | K12: 950 | L12: 130 | M12: 0 | N12: 45 | O12: 650 | P12: 18 | Q12: 6 | R12: 5 | S12: 3 | T12: 8 | U12: 1 | V12: 0 | W12: 1 | X12: 10 | Y12: 7 | Z12: 15 | AA12: 25 | AB12: 35 | AC12: 35 | AD12: 0 | AE12: 35 | AF12: Armored | AG12: TRUE | AH12: TRUE | AI12: FALSE | AJ12: FALSE | AK12: FALSE | AL12: 0 | AM12: 0 | AN12: 0 | AO12: Approach | AP12: 1100 | AQ12: 80 | AR12: 3 | AS12: 850 | AT12: 300 | AU12: 1200 | AV12: 0 | AW12: 0 | AX12: 0 | AY12: 1 | AZ12: 1200 | BA12: 0 | BB12: =IF(B12="all",0,N12+ROUND(VLOOKUP(B12,'Fighter Stats'!$A$6:$E$8,5,FALSE)*O12/'Global Config'!$D$12,0)) -> 130 | BC12: =ROUND(BB12*(1-('Global Config'!$D$36/('Global Config'!$D$36+'Global Config'!$D$23))),0) -> 87 | BD12: Hypothesis | BE12: =IF(AND(A12<>"",H12<=I12,J12<=K12,S12<=R12,R12<=T12,Y12<=X12,X12<=Z12,AT12<=AS12,AS12<=AU12,AW12<=AX12,AY12>=1,L12>=0,M12>=0),"OK","ERROR") -> OK | BF12: Промах оставляет заметный recovery. | BG12: 2 | BH12: 3 | BI12: Startup | BJ12: Startup|Active
A13: bear_rampage_charge | B13: bear | C13: Неудержимый натиск | D13: Special | E13: SignatureApproach | F13: special|signature|approach|strike|unstoppable|wall_impact | G13: 500 | H13: 1600 | I13: 3600 | J13: 200 | K13: 1050 | L13: 300 | M13: 350 | N13: 90 | O13: 1200 | P13: 35 | Q13: 10 | R13: 12 | S13: 8 | T13: 18 | U13: 2 | V13: 0 | W13: 1 | X13: 18 | Y13: 12 | Z13: 26 | AA13: 80 | AB13: 65 | AC13: 70 | AD13: 0 | AE13: 65 | AF13: Unstoppable | AG13: TRUE | AH13: TRUE | AI13: FALSE | AJ13: TRUE | AK13: FALSE | AL13: 0 | AM13: 0 | AN13: 0 | AO13: Approach | AP13: 2600 | AQ13: 180 | AR13: 7 | AS13: 1400 | AT13: 600 | AU13: 1800 | AV13: 150 | AW13: 20 | AX13: 160 | AY13: 1 | AZ13: 2500 | BA13: 4 | BB13: =IF(B13="all",0,N13+ROUND(VLOOKUP(B13,'Fighter Stats'!$A$6:$E$8,5,FALSE)*O13/'Global Config'!$D$12,0)) -> 246 | BC13: =ROUND(BB13*(1-('Global Config'!$D$36/('Global Config'!$D$36+'Global Config'!$D$23))),0) -> 164 | BD13: Hypothesis | BE13: =IF(AND(A13<>"",H13<=I13,J13<=K13,S13<=R13,R13<=T13,Y13<=X13,X13<=Z13,AT13<=AS13,AS13<=AU13,AW13<=AX13,AY13>=1,L13>=0,M13>=0),"OK","ERROR") -> OK | BF13: Late Dodge остаётся контрplay; получает урон во время Unstoppable. | BG13: 3 | BH13: 1 | BI13: Startup | BJ13: Startup|Active | BK13: Stun|Knockdown
A14: bear_earthbreaker | B14: bear | C14: Землелом | D14: Special | E14: SignatureGround | F14: special|signature|heavy|ground|undodgeable|stagger | G14: 470 | H14: 300 | I14: 1700 | J14: 0 | K14: 2200 | L14: 250 | M14: 450 | N14: 80 | O14: 1000 | P14: 30 | Q14: 10 | R14: 14 | S14: 10 | T14: 20 | U14: 2 | V14: 0 | W14: 1 | X14: 17 | Y14: 12 | Z14: 25 | AA14: 75 | AB14: 60 | AC14: 60 | AD14: 0 | AE14: 60 | AF14: Committed | AG14: TRUE | AH14: FALSE | AI14: TRUE | AJ14: FALSE | AK14: FALSE | AL14: 0 | AM14: 0 | AN14: 0 | AO14: None | AP14: 0 | AQ14: 220 | AR14: 10 | AS14: 250 | AT14: 0 | AU14: 500 | AV14: 0 | AW14: 0 | AX14: 0 | AY14: 1 | AZ14: 2500 | BA14: 4 | BB14: =IF(B14="all",0,N14+ROUND(VLOOKUP(B14,'Fighter Stats'!$A$6:$E$8,5,FALSE)*O14/'Global Config'!$D$12,0)) -> 210 | BC14: =ROUND(BB14*(1-('Global Config'!$D$36/('Global Config'!$D$36+'Global Config'!$D$23))),0) -> 140 | BD14: Hypothesis | BE14: =IF(AND(A14<>"",H14<=I14,J14<=K14,S14<=R14,R14<=T14,Y14<=X14,X14<=Z14,AT14<=AS14,AS14<=AU14,AW14<=AX14,AY14>=1,L14>=0,M14>=0),"OK","ERROR") -> OK | BF14: Из geometry можно выйти до impact; DodgeChance не проверяется. | BG14: 3 | BH14: 1 | BI14: Startup
A15: bear_fury_maul | B15: bear | C15: Яростная расправа | D15: Special | E15: SignatureMultiHit | F15: special|signature|multi_hit|finisher|punish | G15: 420 | H15: 0 | I15: 850 | J15: 0 | K15: 1050 | L15: 350 | M15: 650 | N15: 28 | O15: 420 | P15: 10 | Q15: 3 | R15: 6 | S15: 4 | T15: 9 | U15: 12 | V15: 0|3|6|10 | W15: 4 | X15: 22 | Y15: 15 | Z15: 32 | AA15: 100 | AB15: 58 | AC15: 55 | AD15: 0 | AE15: 58 | AF15: UninterruptibleImpact | AG15: TRUE | AH15: TRUE | AI15: FALSE | AJ15: FALSE | AK15: FALSE | AL15: 0 | AM15: 0 | AN15: 0 | AO15: Follow | AP15: 350 | AQ15: 45 | AR15: 3 | AS15: 180 | AT15: 0 | AU15: 300 | AV15: 0 | AW15: 0 | AX15: 0 | AY15: 1 | AZ15: 2500 | BA15: 4 | BB15: =IF(B15="all",0,N15+ROUND(VLOOKUP(B15,'Fighter Stats'!$A$6:$E$8,5,FALSE)*O15/'Global Config'!$D$12,0)) -> 83 | BC15: =ROUND(BB15*(1-('Global Config'!$D$36/('Global Config'!$D$36+'Global Config'!$D$23))),0) -> 55 | BD15: Hypothesis | BE15: =IF(AND(A15<>"",H15<=I15,J15<=K15,S15<=R15,R15<=T15,Y15<=X15,X15<=Z15,AT15<=AS15,AS15<=AU15,AW15<=AX15,AY15>=1,L15>=0,M15>=0),"OK","ERROR") -> OK | BF15: Последний hit использует Punish multiplier 1.8x при Exposed/Stunned. | BG15: 2 | BH15: 1 | BI15: Startup
A16: kangaroo_lead_jab | B16: kangaroo | C16: Передний джеб | D16: Basic | E16: LightStrike | F16: strike|light|rhythm|fallback | G16: 1000 | H16: 100 | I16: 850 | J16: 0 | K16: 950 | L16: 0 | M16: 0 | N16: 22 | O16: 350 | P16: 9 | Q16: 3 | R16: 2 | S16: 1 | T16: 4 | U16: 1 | V16: 0 | W16: 1 | X16: 4 | Y16: 2 | Z16: 7 | AA16: 0 | AB16: 25 | AC16: 22 | AD16: 0 | AE16: 25 | AF16: Committed | AG16: TRUE | AH16: TRUE | AI16: FALSE | AJ16: FALSE | AK16: FALSE | AL16: 0 | AM16: 0 | AN16: 0 | AO16: None | AP16: 0 | AQ16: 15 | AR16: 0 | AS16: 0 | AT16: 0 | AU16: 0 | AV16: 0 | AW16: 0 | AX16: 0 | AY16: 2 | AZ16: 1000 | BA16: 0 | BB16: =IF(B16="all",0,N16+ROUND(VLOOKUP(B16,'Fighter Stats'!$A$6:$E$8,5,FALSE)*O16/'Global Config'!$D$12,0)) -> 57 | BC16: =ROUND(BB16*(1-('Global Config'!$D$36/('Global Config'!$D$36+'Global Config'!$D$23))),0) -> 38 | BD16: Hypothesis | BE16: =IF(AND(A16<>"",H16<=I16,J16<=K16,S16<=R16,R16<=T16,Y16<=X16,X16<=Z16,AT16<=AS16,AS16<=AU16,AW16<=AX16,AY16>=1,L16>=0,M16>=0),"OK","ERROR") -> OK | BF16: Даёт Rhythm только после другой категории. | BG16: 1 | BH16: 1 | BI16: Startup
A17: kangaroo_push_kick | B17: kangaroo | C17: Отталкивающий удар ногой | D17: Basic | E17: PokeStrike | F17: strike|poke|knockback|rhythm | G17: 780 | H17: 900 | I17: 1900 | J17: 400 | K17: 2000 | L17: 120 | M17: 0 | N17: 35 | O17: 550 | P17: 14 | Q17: 5 | R17: 5 | S17: 3 | T17: 8 | U17: 1 | V17: 0 | W17: 1 | X17: 8 | Y17: 5 | Z17: 12 | AA17: 20 | AB17: 32 | AC17: 30 | AD17: 0 | AE17: 32 | AF17: Committed | AG17: TRUE | AH17: TRUE | AI17: FALSE | AJ17: FALSE | AK17: FALSE | AL17: 0 | AM17: 0 | AN17: 0 | AO17: Push | AP17: 0 | AQ17: 55 | AR17: 2 | AS17: 700 | AT17: 250 | AU17: 1000 | AV17: 0 | AW17: 0 | AX17: 0 | AY17: 2 | AZ17: 1200 | BA17: 0 | BB17: =IF(B17="all",0,N17+ROUND(VLOOKUP(B17,'Fighter Stats'!$A$6:$E$8,5,FALSE)*O17/'Global Config'!$D$12,0)) -> 90 | BC17: =ROUND(BB17*(1-('Global Config'!$D$36/('Global Config'!$D$36+'Global Config'!$D$23))),0) -> 60 | BD17: Hypothesis | BE17: =IF(AND(A17<>"",H17<=I17,J17<=K17,S17<=R17,R17<=T17,Y17<=X17,X17<=Z17,AT17<=AS17,AS17<=AU17,AW17<=AX17,AY17>=1,L17>=0,M17>=0),"OK","ERROR") -> OK | BF17: Сохраняет mid range; blocked profile увеличивает recovery на 3 ticks. | BG17: 2 | BH17: 1 | BI17: Startup
A18: kangaroo_bounding_step | B18: kangaroo | C18: Пружинящий шаг | D18: Basic | E18: TempoMovement | F18: movement|adaptive|tempo|rhythm | G18: 850 | H18: 1000 | I18: 2200 | J18: 0 | K18: 0 | L18: 0 | M18: 0 | N18: 0 | O18: 0 | P18: 0 | Q18: 0 | R18: 1 | S18: 1 | T18: 2 | U18: 5 | W18: 0 | X18: 2 | Y18: 1 | Z18: 4 | AA18: 5 | AB18: 12 | AC18: 0 | AD18: 0 | AE18: 12 | AF18: Cancelable | AG18: FALSE | AH18: FALSE | AI18: FALSE | AJ18: FALSE | AK18: TRUE | AL18: 0 | AM18: 0 | AN18: 0 | AO18: Adaptive | AP18: 850 | AQ18: 0 | AR18: 0 | AS18: 0 | AT18: 0 | AU18: 0 | AV18: 0 | AW18: 0 | AX18: 0 | AY18: 3 | AZ18: 1000 | BA18: 0 | BB18: =IF(B18="all",0,N18+ROUND(VLOOKUP(B18,'Fighter Stats'!$A$6:$E$8,5,FALSE)*O18/'Global Config'!$D$12,0)) -> 0 | BC18: =ROUND(BB18*(1-('Global Config'!$D$36/('Global Config'!$D$36+'Global Config'!$D$23))),0) -> 0 | BD18: Hypothesis | BE18: =IF(AND(A18<>"",H18<=I18,J18<=K18,S18<=R18,R18<=T18,Y18<=X18,X18<=Z18,AT18<=AS18,AS18<=AU18,AW18<=AX18,AY18>=1,L18>=0,M18>=0),"OK","ERROR") -> OK | BF18: Tempo только за фактическое добровольное движение. | BG18: 0 | BH18: 1 | BI18: Startup|Active
A19: kangaroo_slip_hop | B19: kangaroo | C19: Скользящий отскок | D19: Basic | E19: DodgeMovement | F19: dodge|retreat|tempo|evade_grab | G19: 650 | H19: 1200 | I19: 2500 | J19: 0 | K19: 0 | L19: 100 | M19: 0 | N19: 0 | O19: 0 | P19: 0 | Q19: 0 | R19: 2 | S19: 1 | T19: 3 | U19: 4 | W19: 0 | X19: 6 | Y19: 4 | Z19: 9 | AA19: 15 | AB19: 50 | AC19: 0 | AD19: 0 | AE19: 80 | AF19: Committed | AG19: FALSE | AH19: FALSE | AI19: FALSE | AJ19: FALSE | AK19: FALSE | AL19: 0 | AM19: 0 | AN19: 650 | AO19: Retreat | AP19: 700 | AQ19: 0 | AR19: 0 | AS19: 0 | AT19: 0 | AU19: 0 | AV19: 0 | AW19: 0 | AX19: 0 | AY19: 1 | AZ19: 1200 | BA19: 0 | BB19: =IF(B19="all",0,N19+ROUND(VLOOKUP(B19,'Fighter Stats'!$A$6:$E$8,5,FALSE)*O19/'Global Config'!$D$12,0)) -> 0 | BC19: =ROUND(BB19*(1-('Global Config'!$D$36/('Global Config'!$D$36+'Global Config'!$D$23))),0) -> 0 | BD19: Hypothesis | BE19: =IF(AND(A19<>"",H19<=I19,J19<=K19,S19<=R19,R19<=T19,Y19<=X19,X19<=Z19,AT19<=AS19,AS19<=AU19,AW19<=AX19,AY19>=1,L19>=0,M19>=0),"OK","ERROR") -> OK | BF19: EvadeGrab требует выхода из grab range; у стены сильно штрафуется. | BG19: 0 | BH19: 1 | BI19: Startup
A20: kangaroo_flying_kick | B20: kangaroo | C20: Летящий удар | D20: Special | E20: SignatureApproach | F20: special|signature|approach|strike|knockback|wall_impact | G20: 520 | H20: 1500 | I20: 3300 | J20: 200 | K20: 1150 | L20: 260 | M20: 350 | N20: 65 | O20: 850 | P20: 24 | Q20: 7 | R20: 7 | S20: 4 | T20: 11 | U20: 1 | V20: 0 | W20: 1 | X20: 14 | Y20: 9 | Z20: 21 | AA20: 60 | AB20: 62 | AC20: 62 | AD20: 0 | AE20: 62 | AF20: Committed | AG20: TRUE | AH20: TRUE | AI20: FALSE | AJ20: TRUE | AK20: FALSE | AL20: 0 | AM20: 0 | AN20: 0 | AO20: Approach | AP20: 2300 | AQ20: 125 | AR20: 5 | AS20: 1100 | AT20: 450 | AU20: 1500 | AV20: 90 | AW20: 10 | AX20: 90 | AY20: 1 | AZ20: 2500 | BA20: 4 | BB20: =IF(B20="all",0,N20+ROUND(VLOOKUP(B20,'Fighter Stats'!$A$6:$E$8,5,FALSE)*O20/'Global Config'!$D$12,0)) -> 150 | BC20: =ROUND(BB20*(1-('Global Config'!$D$36/('Global Config'!$D$36+'Global Config'!$D$23))),0) -> 100 | BD20: Hypothesis | BE20: =IF(AND(A20<>"",H20<=I20,J20<=K20,S20<=R20,R20<=T20,Y20<=X20,X20<=Z20,AT20<=AS20,AS20<=AU20,AW20<=AX20,AY20>=1,L20>=0,M20>=0),"OK","ERROR") -> OK | BF20: Сильный punish, но Block/miss дают длинный recovery. | BG20: 2 | BH20: 1 | BI20: Startup
A21: kangaroo_tail_counter | B21: kangaroo | C21: Контрудар хвостом | D21: Special | E21: SignatureCounter | F21: special|signature|counter|position|rhythm | G21: 460 | H21: 200 | I21: 1500 | J21: 0 | K21: 1600 | L21: 200 | M21: 400 | N21: 55 | O21: 700 | P21: 20 | Q21: 6 | R21: 2 | S21: 1 | T21: 4 | U21: 6 | V21: counter:0 | W21: 1 | X21: 16 | Y21: 10 | Z21: 24 | AA21: 70 | AB21: 75 | AC21: 75 | AD21: 0 | AE21: 90 | AF21: UninterruptibleImpact | AG21: TRUE | AH21: FALSE | AI21: FALSE | AJ21: FALSE | AK21: TRUE | AL21: 0 | AM21: 0 | AN21: 0 | AO21: Swap | AP21: 500 | AQ21: 100 | AR21: 4 | AS21: 450 | AT21: 100 | AU21: 700 | AV21: 0 | AW21: 0 | AX21: 0 | AY21: 1 | AZ21: 2200 | BA21: 0 | BB21: =IF(B21="all",0,N21+ROUND(VLOOKUP(B21,'Fighter Stats'!$A$6:$E$8,5,FALSE)*O21/'Global Config'!$D$12,0)) -> 125 | BC21: =ROUND(BB21*(1-('Global Config'!$D$36/('Global Config'!$D$36+'Global Config'!$D$23))),0) -> 83 | BD21: Hypothesis | BE21: =IF(AND(A21<>"",H21<=I21,J21<=K21,S21<=R21,R21<=T21,Y21<=X21,X21<=Z21,AT21<=AS21,AS21<=AU21,AW21<=AX21,AY21>=1,L21>=0,M21>=0),"OK","ERROR") -> OK | BF21: Legal только после наблюдаемого разрешённого telegraph. | BG21: 2 | BH21: 1 | BI21: Startup
A22: kangaroo_tempo_barrage | B22: kangaroo | C22: Серия в темпе | D22: Special | E22: SignatureMultiHit | F22: special|signature|multi_hit|finisher|rhythm | G22: 420 | H22: 200 | I22: 1600 | J22: 0 | K22: 1600 | L22: 300 | M22: 650 | N22: 18 | O22: 260 | P22: 7 | Q22: 2 | R22: 4 | S22: 2 | T22: 7 | U22: 14 | V22: 0|3|6|9|13 | W22: 5 | X22: 20 | Y22: 13 | Z22: 30 | AA22: 90 | AB22: 57 | AC22: 50 | AD22: 0 | AE22: 57 | AF22: UninterruptibleImpact | AG22: TRUE | AH22: TRUE | AI22: FALSE | AJ22: FALSE | AK22: TRUE | AL22: 0 | AM22: 0 | AN22: 0 | AO22: Follow | AP22: 500 | AQ22: 35 | AR22: 2 | AS22: 120 | AT22: 0 | AU22: 220 | AV22: 0 | AW22: 0 | AX22: 0 | AY22: 1 | AZ22: 2500 | BA22: 4 | BB22: =IF(B22="all",0,N22+ROUND(VLOOKUP(B22,'Fighter Stats'!$A$6:$E$8,5,FALSE)*O22/'Global Config'!$D$12,0)) -> 44 | BC22: =ROUND(BB22*(1-('Global Config'!$D$36/('Global Config'!$D$36+'Global Config'!$D$23))),0) -> 29 | BD22: Hypothesis | BE22: =IF(AND(A22<>"",H22<=I22,J22<=K22,S22<=R22,R22<=T22,Y22<=X22,X22<=Z22,AT22<=AS22,AS22<=AU22,AW22<=AX22,AY22>=1,L22>=0,M22>=0),"OK","ERROR") -> OK | BF22: Один Dodge не отменяет последующие hit groups; финальный hit 1.5x при Exposed. | BG22: 1 | BH22: 1 | BI22: Startup
A23: gorilla_hammer_fist | B23: gorilla | C23: Молотящий кулак | D23: Basic | E23: MediumStrike | F23: strike|medium|pressure|fallback | G23: 1000 | H23: 100 | I23: 950 | J23: 0 | K23: 1050 | L23: 0 | M23: 0 | N23: 35 | O23: 500 | P23: 13 | Q23: 4 | R23: 4 | S23: 2 | T23: 6 | U23: 1 | V23: 0 | W23: 1 | X23: 6 | Y23: 4 | Z23: 9 | AA23: 0 | AB23: 28 | AC23: 30 | AD23: 0 | AE23: 28 | AF23: Committed | AG23: TRUE | AH23: TRUE | AI23: FALSE | AJ23: FALSE | AK23: FALSE | AL23: 0 | AM23: 0 | AN23: 0 | AO23: None | AP23: 0 | AQ23: 35 | AR23: 0 | AS23: 0 | AT23: 0 | AU23: 0 | AV23: 0 | AW23: 0 | AX23: 0 | AY23: 2 | AZ23: 1000 | BA23: 0 | BB23: =IF(B23="all",0,N23+ROUND(VLOOKUP(B23,'Fighter Stats'!$A$6:$E$8,5,FALSE)*O23/'Global Config'!$D$12,0)) -> 90 | BC23: =ROUND(BB23*(1-('Global Config'!$D$36/('Global Config'!$D$36+'Global Config'!$D$23))),0) -> 60 | BD23: Hypothesis | BE23: =IF(AND(A23<>"",H23<=I23,J23<=K23,S23<=R23,R23<=T23,Y23<=X23,X23<=Z23,AT23<=AS23,AS23<=AU23,AW23<=AX23,AY23>=1,L23>=0,M23>=0),"OK","ERROR") -> OK | BF23: Стабильный pressure action. | BG23: 2 | BH23: 1 | BI23: Startup
A24: gorilla_driving_shove | B24: gorilla | C24: Давящий толчок | D24: Basic | E24: ShoveStrike | F24: strike|knockback|grip_generator|position | G24: 820 | H24: 100 | I24: 800 | J24: 0 | K24: 900 | L24: 110 | M24: 0 | N24: 20 | O24: 250 | P24: 8 | Q24: 3 | R24: 4 | S24: 2 | T24: 6 | U24: 1 | V24: 0 | W24: 1 | X24: 8 | Y24: 5 | Z24: 12 | AA24: 18 | AB24: 36 | AC24: 35 | AD24: 0 | AE24: 36 | AF24: Committed | AG24: TRUE | AH24: TRUE | AI24: FALSE | AJ24: FALSE | AK24: FALSE | AL24: 0 | AM24: 0 | AN24: 0 | AO24: Push | AP24: 0 | AQ24: 60 | AR24: 2 | AS24: 900 | AT24: 350 | AU24: 1250 | AV24: 0 | AW24: 0 | AX24: 0 | AY24: 2 | AZ24: 1200 | BA24: 0 | BB24: =IF(B24="all",0,N24+ROUND(VLOOKUP(B24,'Fighter Stats'!$A$6:$E$8,5,FALSE)*O24/'Global Config'!$D$12,0)) -> 48 | BC24: =ROUND(BB24*(1-('Global Config'!$D$36/('Global Config'!$D$36+'Global Config'!$D$23))),0) -> 32 | BD24: Hypothesis | BE24: =IF(AND(A24<>"",H24<=I24,J24<=K24,S24<=R24,R24<=T24,Y24<=X24,X24<=Z24,AT24<=AS24,AS24<=AU24,AW24<=AX24,AY24>=1,L24>=0,M24>=0),"OK","ERROR") -> OK | BF24: Grip начисляется только на resolved hit. | BG24: 2 | BH24: 1 | BI24: Startup
A25: gorilla_high_guard | B25: gorilla | C25: Высокая защита | D25: Basic | E25: Block | F25: block|defense|grip_generator | G25: 700 | H25: 0 | I25: 1800 | J25: 0 | K25: 0 | L25: 90 | M25: 0 | N25: 0 | O25: 0 | P25: 0 | Q25: 0 | R25: 2 | S25: 1 | T25: 4 | U25: 12 | W25: 0 | X25: 6 | Y25: 4 | Z25: 9 | AA25: 15 | AB25: 40 | AC25: 0 | AD25: 0 | AE25: 85 | AF25: Committed | AG25: FALSE | AH25: FALSE | AI25: FALSE | AJ25: FALSE | AK25: FALSE | AL25: 700 | AM25: 650 | AN25: 0 | AO25: None | AP25: 0 | AQ25: 0 | AR25: 0 | AS25: 0 | AT25: 0 | AU25: 0 | AV25: 0 | AW25: 0 | AX25: 0 | AY25: 1 | AZ25: 1200 | BA25: 0 | BB25: =IF(B25="all",0,N25+ROUND(VLOOKUP(B25,'Fighter Stats'!$A$6:$E$8,5,FALSE)*O25/'Global Config'!$D$12,0)) -> 0 | BC25: =ROUND(BB25*(1-('Global Config'!$D$36/('Global Config'!$D$36+'Global Config'!$D$23))),0) -> 0 | BD25: Hypothesis | BE25: =IF(AND(A25<>"",H25<=I25,J25<=K25,S25<=R25,R25<=T25,Y25<=X25,X25<=Z25,AT25<=AS25,AS25<=AU25,AW25<=AX25,AY25>=1,L25>=0,M25>=0),"OK","ERROR") -> OK | BF25: Grab и GuardBreak остаются основным контрplay. | BG25: 0 | BH25: 1 | BI25: Startup
A26: gorilla_clinch_check | B26: gorilla | C26: Проверка клинча | D26: Basic | E26: Grab | F26: grab|position|grip_generator|pull | G26: 620 | H26: 0 | I26: 650 | J26: 0 | K26: 700 | L26: 120 | M26: 0 | N26: 0 | O26: 0 | P26: 0 | Q26: 0 | R26: 5 | S26: 3 | T26: 8 | U26: 1 | V26: grab:0 | W26: 0 | X26: 10 | Y26: 7 | Z26: 15 | AA26: 30 | AB26: 45 | AC26: 0 | AD26: 55 | AE26: 55 | AF26: Committed | AG26: FALSE | AH26: FALSE | AI26: FALSE | AJ26: FALSE | AK26: TRUE | AL26: 0 | AM26: 0 | AN26: 0 | AO26: Pull | AP26: 400 | AQ26: 35 | AR26: 0 | AS26: 400 | AT26: 150 | AU26: 600 | AV26: 0 | AW26: 0 | AX26: 0 | AY26: 1 | AZ26: 1200 | BA26: 0 | BB26: =IF(B26="all",0,N26+ROUND(VLOOKUP(B26,'Fighter Stats'!$A$6:$E$8,5,FALSE)*O26/'Global Config'!$D$12,0)) -> 0 | BC26: =ROUND(BB26*(1-('Global Config'!$D$36/('Global Config'!$D$36+'Global Config'!$D$23))),0) -> 0 | BD26: Hypothesis | BE26: =IF(AND(A26<>"",H26<=I26,J26<=K26,S26<=R26,R26<=T26,Y26<=X26,X26<=Z26,AT26<=AS26,AS26<=AU26,AW26<=AX26,AY26>=1,L26>=0,M26>=0),"OK","ERROR") -> OK | BF26: Немедленный pull/release без длительного удержания. | BG26: 0 | BH26: 1 | BI26: Startup
A27: gorilla_pivot_throw | B27: gorilla | C27: Разворотный бросок | D27: Special | E27: SignatureGrab | F27: special|signature|grab|throw|swap|knockdown | G27: 500 | H27: 0 | I27: 650 | J27: 0 | K27: 700 | L27: 230 | M27: 400 | N27: 60 | O27: 700 | P27: 22 | Q27: 0 | R27: 7 | S27: 4 | T27: 11 | U27: 6 | V27: grab:0|throw:5 | W27: 1 | X27: 15 | Y27: 10 | Z27: 23 | AA27: 70 | AB27: 70 | AC27: 0 | AD27: 75 | AE27: 75 | AF27: Committed | AG27: FALSE | AH27: FALSE | AI27: FALSE | AJ27: FALSE | AK27: TRUE | AL27: 0 | AM27: 0 | AN27: 0 | AO27: Swap | AP27: 900 | AQ27: 170 | AR27: 8 | AS27: 900 | AT27: 400 | AU27: 1300 | AV27: 0 | AW27: 0 | AX27: 0 | AY27: 1 | AZ27: 2500 | BA27: 4 | BB27: =IF(B27="all",0,N27+ROUND(VLOOKUP(B27,'Fighter Stats'!$A$6:$E$8,5,FALSE)*O27/'Global Config'!$D$12,0)) -> 137 | BC27: =ROUND(BB27*(1-('Global Config'!$D$36/('Global Config'!$D$36+'Global Config'!$D$23))),0) -> 91 | BD27: Hypothesis | BE27: =IF(AND(A27<>"",H27<=I27,J27<=K27,S27<=R27,R27<=T27,Y27<=X27,X27<=Z27,AT27<=AS27,AS27<=AU27,AW27<=AX27,AY27>=1,L27>=0,M27>=0),"OK","ERROR") -> OK | BF27: MaxHoldTicks=6; reversal у собственной стены. | BG27: 0 | BH27: 1 | BI27: Startup
A28: gorilla_overhead_pound | B28: gorilla | C28: Удар сверху | D28: Special | E28: HeavyGround | F28: special|heavy|ground_hit|stagger|punish | G28: 440 | H28: 100 | I28: 950 | J28: 0 | K28: 1050 | L28: 260 | M28: 350 | N28: 85 | O28: 1050 | P28: 30 | Q28: 9 | R28: 12 | S28: 8 | T28: 18 | U28: 1 | V28: 0 | W28: 1 | X28: 16 | Y28: 11 | Z28: 24 | AA28: 70 | AB28: 63 | AC28: 65 | AD28: 0 | AE28: 63 | AF28: Committed | AG28: TRUE | AH28: TRUE | AI28: FALSE | AJ28: FALSE | AK28: FALSE | AL28: 0 | AM28: 0 | AN28: 0 | AO28: None | AP28: 0 | AQ28: 240 | AR28: 10 | AS28: 250 | AT28: 0 | AU28: 450 | AV28: 0 | AW28: 0 | AX28: 0 | AY28: 1 | AZ28: 2200 | BA28: 3 | BB28: =IF(B28="all",0,N28+ROUND(VLOOKUP(B28,'Fighter Stats'!$A$6:$E$8,5,FALSE)*O28/'Global Config'!$D$12,0)) -> 201 | BC28: =ROUND(BB28*(1-('Global Config'!$D$36/('Global Config'!$D$36+'Global Config'!$D$23))),0) -> 134 | BD28: Hypothesis | BE28: =IF(AND(A28<>"",H28<=I28,J28<=K28,S28<=R28,R28<=T28,Y28<=X28,X28<=Z28,AT28<=AS28,AS28<=AU28,AW28<=AX28,AY28>=1,L28>=0,M28>=0),"OK","ERROR") -> OK | BF28: Высокий вес только против Stunned/KnockedDown/Exposed. | BG28: 3 | BH28: 1 | BI28: Startup
A29: gorilla_wall_breaker | B29: gorilla | C29: Сокрушение о стену | D29: Special | E29: SignatureWallGrab | F29: special|signature|grab|wall_impact|finisher|knockdown | G29: 400 | H29: 0 | I29: 650 | J29: 0 | K29: 700 | L29: 320 | M29: 650 | N29: 75 | O29: 800 | P29: 28 | Q29: 0 | R29: 8 | S29: 5 | T29: 12 | U29: 4 | V29: grab:0|wall:3 | W29: 1 | X29: 20 | Y29: 14 | Z29: 30 | AA29: 100 | AB29: 78 | AC29: 0 | AD29: 82 | AE29: 82 | AF29: Committed | AG29: FALSE | AH29: FALSE | AI29: FALSE | AJ29: TRUE | AK29: TRUE | AL29: 0 | AM29: 0 | AN29: 0 | AO29: Push | AP29: 1000 | AQ29: 230 | AR29: 10 | AS29: 1000 | AT29: 300 | AU29: 1400 | AV29: 250 | AW29: 40 | AX29: 180 | AY29: 1 | AZ29: 2500 | BA29: 4 | BB29: =IF(B29="all",0,N29+ROUND(VLOOKUP(B29,'Fighter Stats'!$A$6:$E$8,5,FALSE)*O29/'Global Config'!$D$12,0)) -> 163 | BC29: =ROUND(BB29*(1-('Global Config'!$D$36/('Global Config'!$D$36+'Global Config'!$D$23))),0) -> 109 | BD29: Hypothesis | BE29: =IF(AND(A29<>"",H29<=I29,J29<=K29,S29<=R29,R29<=T29,Y29<=X29,X29<=Z29,AT29<=AS29,AS29<=AU29,AW29<=AX29,AY29>=1,L29>=0,M29>=0),"OK","ERROR") -> OK | BF29: Legal только в wall zone и при отсутствии GrabLockout. | BG29: 0 | BH29: 1 | BI29: Startup

Sheet Passives
A1: Passive Skills
A2: Шесть пассивов стартовых животных
A3: Все trigger chains имеют InternalCooldown или MaxActivations. Пассив не может отменять MinDamage, GrabLockout, ControlImmunity или MaxHoldTicks.
A5: Passive ID | B5: Animal ID | C5: Display Name RU | D5: Trigger | E5: Conditions | F5: Effect ID | G5: Modifier Stat 1 | H5: Operation 1 | I5: Value 1 | J5: Modifier Stat 2 | K5: Operation 2 | L5: Value 2 | M5: Duration Ticks | N5: Internal Cooldown Ticks | O5: Stack Cap | P5: Max Activations / Tick | Q5: Max Activations / Battle | R5: Resource Gain | S5: Weight Multiplier FP | T5: Tags | U5: Status | V5: Validation | W5: Notes RU
A6: bear_thick_hide | B6: bear | C6: Толстая шкура | D6: OnDamageTaken | E6: valid_strike; internal_cooldown_ready | F6: effect_bear_thick_hide | G6: Armor | H6: Multiply | I6: 1150 | J6: ControlResistance | K6: Multiply | L6: 1150 | M6: 25 | N6: 50 | O6: 1 | P6: 1 | Q6: 99 | R6: 0 | S6: 1000 | T6: defense|comeback | U6: Hypothesis | V6: =IF(AND(A6<>"",B6<>"",P6>=1,Q6>=1,O6>=1,S6>=250,S6<=3000),"OK","ERROR") -> OK | W6: Refresh/StrongestWins; не опускает damage ниже MinDamage.
A7: bear_pressure_fuels_rage | B7: bear | C7: Давление питает ярость | D7: OnDamageTaken|OnBlockedHeavy|OnHeavyHit | E7: eligible_source_event; once_per_event | G7: RageGain | H7: Multiply | I7: 1250 | J7: SignatureWeight | K7: Multiply | L7: 1125 | M7: 0 | N7: 0 | O7: 1 | P7: 3 | Q7: 999 | R7: 0 | S7: 1125 | T7: resource|signature|comeback | U7: Hypothesis | V7: =IF(AND(A7<>"",B7<>"",P7>=1,Q7>=1,O7>=1,S7>=250,S7<=3000),"OK","ERROR") -> OK | W7: Chip eligibility задаётся trigger filter; cap per tick обязателен.
A8: kangaroo_never_still | B8: kangaroo | C8: Всегда в движении | D8: OnVoluntaryDistanceMoved|OnTempoDecayStart | E8: voluntary_movement_only | G8: TempoPerUnit | H8: Multiply | I8: 1250 | J8: DecayGraceTicks | K8: Add | L8: 10 | M8: 0 | N8: 0 | O8: 1 | P8: 1 | Q8: 999 | R8: 0 | S8: 1100 | T8: movement|resource | U8: Hypothesis | V8: =IF(AND(A8<>"",B8<>"",P8>=1,Q8>=1,O8>=1,S8>=250,S8<=3000),"OK","ERROR") -> OK | W8: Forced movement и separation correction не считаются.
A9: kangaroo_clean_rhythm | B9: kangaroo | C9: Чистый ритм | D9: OnNewCategoryHit | E9: category_changed; internal_cooldown_ready | F9: effect_kangaroo_clean_rhythm | G9: Precision | H9: Add | I9: 8 | J9: ActionSpeed | K9: Add | L9: 5 | M9: 20 | N9: 8 | O9: 3 | P9: 1 | Q9: 99 | R9: 60 | S9: 1100 | T9: rhythm|resource|speed | U9: Hypothesis | V9: =IF(AND(A9<>"",B9<>"",P9>=1,Q9>=1,O9>=1,S9>=250,S9<=3000),"OK","ERROR") -> OK | W9: Multi-hit считается одной category opportunity; hard control сбрасывает.
A10: gorilla_territorial_pressure | B10: gorilla | C10: Территориальное давление | D10: EndOfTick|OnDrivingShove | E10: opponent_in_wall_zone; engagement; not_hard_controlled | F10: effect_gorilla_wall_pressure | G10: WallActionWeight | H10: Multiply | I10: 1250 | J10: GripGain | K10: Add | L10: 10 | M10: 10 | N10: 5 | O10: 1 | P10: 1 | Q10: 999 | R10: 10 | S10: 1250 | T10: wall|resource|position | U10: Hypothesis | V10: =IF(AND(A10<>"",B10<>"",P10>=1,Q10>=1,O10>=1,S10>=250,S10<=3000),"OK","ERROR") -> OK | W10: Rate-limited; не начисляется вне engagement.
A11: gorilla_iron_grip | B11: gorilla | C11: Железная хватка | D11: OnGrabStarted|OnGrabResolved | E11: grab_legal; once_per_lifecycle | F11: effect_gorilla_iron_grip | G11: GrabPriority | H11: Add | I11: 8 | J11: ControlPower | K11: Add | L11: 12 | M11: 12 | N11: 15 | O11: 1 | P11: 1 | Q11: 99 | R11: 0 | S11: 1150 | T11: grab|control | U11: Hypothesis | V11: =IF(AND(A11<>"",B11<>"",P11>=1,Q11>=1,O11>=1,S11>=250,S11<=3000),"OK","ERROR") -> OK | W11: Не изменяет MaxHoldTicks, GrabLockout или immunity.

Sheet Effects
A1: Effects
A2: Общие временные эффекты, stacking policies и anti-loop окна
A3: State Stunned/KnockedDown/Grabbed остаётся в машине состояний; здесь находятся только эффекты, модификаторы, immunity и lockout.
A5: Effect ID | B5: Display Name RU | C5: Duration Ticks | D5: Expiry Boundary | E5: Stack Group | F5: Stack Policy | G5: Stack Cap | H5: Compare Key | I5: Modifier Stat 1 | J5: Operation 1 | K5: Value 1 | L5: Modifier Stat 2 | M5: Operation 2 | N5: Value 2 | O5: Tags | P5: Max Activations / Tick | Q5: Max Activations / Battle | R5: Internal Cooldown Ticks | S5: Lookup Profile | T5: Status | U5: Validation | V5: Notes RU | W5: Priority | X5: Refresh Rule | Y5: Semantic Role
A6: effect_bear_thick_hide | B6: Толстая шкура: усиление | C6: 25 | D6: ExpireAfterTick | E6: bear_thick_hide | F6: StrongestWins | G6: 1 | H6: Value1 | I6: Armor | J6: Multiply | K6: 1150 | L6: ControlResistance | M6: Multiply | N6: 1150 | O6: buff|defense | P6: 1 | Q6: 99 | R6: 50 | T6: Hypothesis | U6: =IF(AND(A6<>"",C6>=0,G6>=1,P6>=1,Q6>=1),"OK","ERROR") -> OK | V6: Источник — passive.bear_thick_hide. | W6: 0 | X6: ResetDuration | Y6: None
A7: effect_kangaroo_clean_rhythm | B7: Чистый ритм | C7: 20 | D7: ExpireAfterTick | E7: kangaroo_clean_rhythm | F7: AddStacks | G7: 3 | H7: StackCount | I7: Precision | J7: Add | K7: 8 | L7: ActionSpeed | M7: Add | N7: 5 | O7: buff|rhythm|speed | P7: 1 | Q7: 99 | R7: 8 | T7: Hypothesis | U7: =IF(AND(A7<>"",C7>=0,G7>=1,P7>=1,Q7>=1),"OK","ERROR") -> OK | V7: Сброс при repeat category или hard control. | W7: 0 | X7: ResetDuration | Y7: None
A8: effect_gorilla_wall_pressure | B8: Территориальное давление | C8: 10 | D8: ExpireAfterTick | E8: gorilla_wall_pressure | F8: Refresh | G8: 1 | H8: DurationTicks | I8: WallActionWeight | J8: Multiply | K8: 1250 | L8: GripGain | M8: Add | N8: 10 | O8: buff|wall|resource | P8: 1 | Q8: 999 | R8: 5 | T8: Hypothesis | U8: =IF(AND(A8<>"",C8>=0,G8>=1,P8>=1,Q8>=1),"OK","ERROR") -> OK | V8: Действует только пока соблюдены wall/engagement conditions. | W8: 0 | X8: ResetDuration | Y8: None
A9: effect_gorilla_iron_grip | B9: Железная хватка | C9: 12 | D9: ExpireAfterTick | E9: gorilla_iron_grip | F9: Refresh | G9: 1 | H9: DurationTicks | I9: GrabPriority | J9: Add | K9: 8 | L9: ControlPower | M9: Add | N9: 12 | O9: buff|grab|control | P9: 1 | Q9: 99 | R9: 15 | T9: Hypothesis | U9: =IF(AND(A9<>"",C9>=0,G9>=1,P9>=1,Q9>=1),"OK","ERROR") -> OK | V9: Не изменяет anti-loop limits. | W9: 0 | X9: ResetDuration | Y9: None
A10: effect_guard_broken | B10: Защита сломана | C10: 15 | D10: ExpireAfterTick | E10: guard_broken | F10: Refresh | G10: 1 | H10: DurationTicks | I10: Guard | J10: Add | K10: -30 | L10: BlockWeight | M10: Multiply | N10: 650 | O10: debuff|guard_break|exposed | P10: 1 | Q10: 99 | R10: 0 | T10: Hypothesis | U10: =IF(AND(A10<>"",C10>=0,G10>=1,P10>=1,Q10>=1),"OK","ERROR") -> OK | V10: Не отключает Block полностью. | W10: 0 | X10: ResetDuration | Y10: GuardBreak
A11: effect_exposed | B11: Открыт для наказания | C11: 12 | D11: ExpireAfterTick | E11: exposed | F11: Refresh | G11: 1 | H11: DurationTicks | I11: DamageTaken | J11: Multiply | K11: 1250 | L11: PunishWeight | M11: Multiply | N11: 1400 | O11: debuff|exposed|punish | P11: 1 | Q11: 99 | R11: 0 | T11: Hypothesis | U11: =IF(AND(A11<>"",C11>=0,G11>=1,P11>=1,Q11>=1),"OK","ERROR") -> OK | V11: Все усиления объясняются reason code Exposed. | W11: 0 | X11: ResetDuration | Y11: None
A12: effect_control_fatigue | B12: Усталость от контроля | C12: 100 | D12: ExpireAfterTick | E12: control_fatigue | F12: AddStacks | G12: 3 | H12: StackCount | I12: HardControlDuration | J12: Multiply | K12: 1000 | M12: Override | N12: 0 | O12: debuff|hard_control|anti_loop | P12: 1 | Q12: 999 | R12: 0 | S12: 1000|750|500|250 | T12: Hypothesis | U12: =IF(AND(A12<>"",C12>=0,G12>=1,P12>=1,Q12>=1),"OK","ERROR") -> OK | V12: При stack 3 создаёт ControlImmunity. | W12: 0 | X12: ResetDuration | Y12: ControlFatigue
A13: effect_control_immunity | B13: Иммунитет к контролю | C13: 25 | D13: ExpireAfterTick | E13: control_immunity | F13: Reject | G13: 1 | H13: DurationTicks | I13: HardControlAllowed | J13: Override | K13: 0 | M13: Override | N13: 0 | O13: buff|immunity|anti_loop | P13: 1 | Q13: 999 | R13: 0 | T13: Hypothesis | U13: =IF(AND(A13<>"",C13>=0,G13>=1,P13>=1,Q13>=1),"OK","ERROR") -> OK | V13: Новый hard control не refresh-ит immunity. | W13: 0 | X13: ResetDuration | Y13: ControlImmunity
A14: effect_grab_lockout | B14: Запрет повторного захвата | C14: 20 | D14: ExpireAfterTick | E14: grab_lockout | F14: Reject | G14: 1 | H14: DurationTicks | I14: GrabAllowed | J14: Override | K14: 0 | M14: Override | N14: 0 | O14: debuff|grab|anti_loop | P14: 1 | Q14: 999 | R14: 0 | T14: Hypothesis | U14: =IF(AND(A14<>"",C14>=0,G14>=1,P14>=1,Q14>=1),"OK","ERROR") -> OK | V14: Блокирует любой новый grab до окончания. | W14: 0 | X14: ResetDuration | Y14: GrabLockout
A15: effect_wakeup_immunity | B15: Защита после падения | C15: 25 | D15: ExpireAfterTick | E15: wakeup_immunity | F15: Reject | G15: 1 | H15: DurationTicks | I15: KnockdownAllowed | J15: Override | K15: 0 | M15: Override | N15: 0 | O15: buff|knockdown|anti_loop | P15: 1 | Q15: 999 | R15: 0 | T15: Hypothesis | U15: =IF(AND(A15<>"",C15>=0,G15>=1,P15>=1,Q15>=1),"OK","ERROR") -> OK | V15: GroundHit damage разрешён, новый KnockedDown — нет. | W15: 0 | X15: ResetDuration | Y15: WakeupImmunity

Sheet Tactics
A1: Tactics
A2: Четыре универсальные тактики как множители тегов и ситуаций
A3: Тактика меняет только веса выбора и perception delay; скрытых бонусов урона против AnimalId нет.
A5: Tactic ID | B5: Display Name RU | C5: Approach FP | D5: Retreat FP | E5: Light FP | F5: Heavy FP | G5: Block FP | H5: Dodge FP | I5: Counter FP | J5: Grab FP | K5: Signature FP | L5: Resource Generator FP | M5: Resource Spender FP | N5: Target Recovery FP | O5: Target Wall FP | P5: Self Wall FP | Q5: Low HP FP | R5: Perception Delay Ticks | S5: Repeat Penalty FP | T5: Notes RU | U5: Status | V5: Validation
A6: tactic_pressure | B6: Давление | C6: 1250 | D6: 750 | E6: 1150 | F6: 1100 | G6: 850 | H6: 850 | I6: 800 | J6: 1100 | K6: 1050 | L6: 1000 | M6: 1150 | N6: 1200 | O6: 1150 | P6: 900 | Q6: 1000 | R6: 5 | S6: 850 | T6: Сближается и раньше тратит энергию; уязвима к counter и стене. | U6: Hypothesis | V6: =IF(AND(A6<>"",C6>=250,C6<=3000,D6>=250,D6<=3000,K6>=250,K6<=3000,R6>=1,S6>=250,S6<=1000),"OK","ERROR") -> OK
A7: tactic_counter | B7: Ответная игра | C7: 850 | D7: 1100 | E7: 900 | F7: 900 | G7: 1350 | H7: 1300 | I7: 1450 | J7: 1050 | K7: 950 | L7: 1050 | M7: 850 | N7: 1400 | O7: 900 | P7: 1050 | Q7: 1150 | R7: 3 | S7: 750 | T7: Сохраняет ресурс и реагирует на telegraph; может отдать пространство. | U7: Hypothesis | V7: =IF(AND(A7<>"",C7>=250,C7<=3000,D7>=250,D7<=3000,K7>=250,K7<=3000,R7>=1,S7>=250,S7<=1000),"OK","ERROR") -> OK
A8: tactic_position | B8: Позиция | C8: 1000 | D8: 1250 | E8: 900 | F8: 950 | G8: 1000 | H8: 1150 | I8: 1050 | J8: 1100 | K8: 1050 | L8: 1150 | M8: 950 | N8: 1050 | O8: 1400 | P8: 1350 | Q8: 1000 | R8: 5 | S8: 800 | T8: Держит preferred range, использует knockback, escape и wall opportunities. | U8: Hypothesis | V8: =IF(AND(A8<>"",C8>=250,C8<=3000,D8>=250,D8<=3000,K8>=250,K8<=3000,R8>=1,S8>=250,S8<=1000),"OK","ERROR") -> OK
A9: tactic_signature | B9: Фирменный план | C9: 1050 | D9: 900 | E9: 850 | F9: 1000 | G9: 950 | H9: 950 | I9: 1000 | J9: 1050 | K9: 1450 | L9: 1350 | M9: 1250 | N9: 1150 | O9: 1200 | P9: 1000 | Q9: 1200 | R9: 5 | S9: 800 | T9: Копит уникальный ресурс и использует opportunity profile; план читаем. | U9: Hypothesis | V9: =IF(AND(A9<>"",C9>=250,C9<=3000,D9>=250,D9<=3000,K9>=250,K9<=3000,R9>=1,S9>=250,S9<=1000),"OK","ERROR") -> OK

Sheet Gear
A1: Gear
A2: Девять абстрактных предметов для трёх обязательных слотов
A3: Каждый предмет имеет одинаковый NormalizedValue в контрольном режиме. Прямые bonus_vs_animal запрещены.
A5: Gear ID | B5: Display Name RU | C5: Slot | D5: Stat 1 | E5: Operation 1 | F5: Value 1 | G5: Stat 2 | H5: Operation 2 | I5: Value 2 | J5: Tags | K5: Normalized Value FP | L5: Status | M5: Validation | N5: Notes RU | O5: Priority
A6: gear_offense_power_wraps | B6: Силовые бинты | C6: Offense | D6: Power | E6: Add | F6: 12 | H6: Add | I6: 0 | J6: power|strike | K6: 1000 | L6: Hypothesis | M6: =IF(AND(A6<>"",OR(C6="Offense",C6="Defense",C6="Utility"),D6<>"",K6>0),"OK","ERROR") -> OK | N6: Базовый урон без видового бонуса. | O6: 0
A7: gear_offense_precision_lens | B7: Прицельный визор | C7: Offense | D7: Precision | E7: Add | F7: 15 | H7: Add | I7: 0 | J7: precision|anti_dodge | K7: 1000 | L7: Hypothesis | M7: =IF(AND(A7<>"",OR(C7="Offense",C7="Defense",C7="Utility"),D7<>"",K7>0),"OK","ERROR") -> OK | N7: Контрplay активному Dodge через рейтинг. | O7: 0
A8: gear_offense_guardbreaker | B8: Накладки пробоя | C8: Offense | D8: GuardBreak | E8: Add | F8: 15 | H8: Add | I8: 0 | J8: guard_break|anti_block | K8: 1000 | L8: Hypothesis | M8: =IF(AND(A8<>"",OR(C8="Offense",C8="Defense",C8="Utility"),D8<>"",K8>0),"OK","ERROR") -> OK | N8: Не читает вид соперника. | O8: 0
A9: gear_defense_vital_harness | B9: Жизненный пояс | C9: Defense | D9: MaxHealth | E9: Add | F9: 120 | H9: Add | I9: 0 | J9: health|survival | K9: 1000 | L9: Hypothesis | M9: =IF(AND(A9<>"",OR(C9="Offense",C9="Defense",C9="Utility"),D9<>"",K9>0),"OK","ERROR") -> OK | N9: Прямая выживаемость. | O9: 0
A10: gear_defense_reinforced_hide | B10: Укреплённая защита | C10: Defense | D10: Armor | E10: Add | F10: 18 | H10: Add | I10: 0 | J10: armor|anti_multi_hit | K10: 1000 | L10: Hypothesis | M10: =IF(AND(A10<>"",OR(C10="Offense",C10="Defense",C10="Utility"),D10<>"",K10>0),"OK","ERROR") -> OK | N10: Особенно заметна против серий. | O10: 0
A11: gear_defense_control_brace | B11: Стабилизатор контроля | C11: Defense | D11: ControlResistance | E11: Add | F11: 18 | H11: Add | I11: 0 | J11: control_resistance|anti_control | K11: 1000 | L11: Hypothesis | M11: =IF(AND(A11<>"",OR(C11="Offense",C11="Defense",C11="Utility"),D11<>"",K11>0),"OK","ERROR") -> OK | N11: Сокращает stagger/hard control через формулу. | O11: 0
A12: gear_utility_sprint_soles | B12: Скоростные подошвы | C12: Utility | D12: MoveSpeed | E12: Add | F12: 12 | H12: Add | I12: 0 | J12: movement|position | K12: 1000 | L12: Hypothesis | M12: =IF(AND(A12<>"",OR(C12="Offense",C12="Defense",C12="Utility"),D12<>"",K12>0),"OK","ERROR") -> OK | N12: Улучшает добровольное движение. | O12: 0
A13: gear_utility_quickening_cord | B13: Шнур ускорения | C13: Utility | D13: ActionSpeed | E13: Add | F13: 12 | H13: Add | I13: 0 | J13: action_speed|tempo | K13: 1000 | L13: Hypothesis | M13: =IF(AND(A13<>"",OR(C13="Offense",C13="Defense",C13="Utility"),D13<>"",K13>0),"OK","ERROR") -> OK | N13: Изменяет startup/recovery в пределах action min/max. | O13: 0
A14: gear_utility_energy_cell | B14: Энергетический модуль | C14: Utility | D14: MaxEnergy | E14: Add | F14: 120 | G14: EnergyRegen | H14: Add | I14: 2 | J14: energy|resource_economy | K14: 1000 | L14: Hypothesis | M14: =IF(AND(A14<>"",OR(C14="Offense",C14="Defense",C14="Utility"),D14<>"",K14>0),"OK","ERROR") -> OK | N14: Не изменяет уникальный ресурс напрямую. | O14: 0

Sheet Test Builds
A1: Test Builds
A2: Двенадцать контрольных сборок для baseline, контрматчапов и signature usage
A3: Валидация проверяет 2 разных Special своего животного, 1 Passive, три правильных gear slot и существующую тактику.
A5: Build ID | B5: Display Name RU | C5: Animal ID | D5: Special 1 | E5: Special 2 | F5: Passive | G5: Offense Gear | H5: Defense Gear | I5: Utility Gear | J5: Tactic ID | K5: Power Band | L5: Intended Matchup | M5: Status | N5: Validation | O5: Notes RU
A6: build_bear_default | B6: Медведь — базовый | C6: bear | D6: bear_rampage_charge | E6: bear_earthbreaker | F6: bear_thick_hide | G6: gear_offense_power_wraps | H6: gear_defense_reinforced_hide | I6: gear_utility_energy_cell | J6: tactic_pressure | K6: Normalized 1000 | L6: baseline | M6: Hypothesis | N6: =IF(AND(D6<>E6,COUNTIFS(Actions!$A$6:$A$29,D6,Actions!$B$6:$B$29,C6,Actions!$D$6:$D$29,"Special")=1,COUNTIFS(Actions!$A$6:$A$29,E6,Actions!$B$6:$B$29,C6,Actions!$D$6:$D$29,"Special")=1,COUNTIFS(Passives!$A$6:$A$11,F6,Passives!$B$6:$B$11,C6)=1,COUNTIFS(Gear!$A$6:$A$14,G6,Gear!$C$6:$C$14,"Offense")=1,COUNTIFS(Gear!$A$6:$A$14,H6,Gear!$C$6:$C$14,"Defense")=1,COUNTIFS(Gear!$A$6:$A$14,I6,Gear!$C$6:$C$14,"Utility")=1,COUNTIF(Tactics!$A$6:$A$9,J6)=1),"OK","ERROR") -> OK | O6: Контрольная сборка первого пакетного запуска.
A7: build_bear_anti_kite | B7: Медведь — против дистанции | C7: bear | D7: bear_rampage_charge | E7: bear_fury_maul | F7: bear_pressure_fuels_rage | G7: gear_offense_precision_lens | H7: gear_defense_vital_harness | I7: gear_utility_sprint_soles | J7: tactic_position | K7: Normalized 1000 | L7: vs_kangaroo | M7: Hypothesis | N7: =IF(AND(D7<>E7,COUNTIFS(Actions!$A$6:$A$29,D7,Actions!$B$6:$B$29,C7,Actions!$D$6:$D$29,"Special")=1,COUNTIFS(Actions!$A$6:$A$29,E7,Actions!$B$6:$B$29,C7,Actions!$D$6:$D$29,"Special")=1,COUNTIFS(Passives!$A$6:$A$11,F7,Passives!$B$6:$B$11,C7)=1,COUNTIFS(Gear!$A$6:$A$14,G7,Gear!$C$6:$C$14,"Offense")=1,COUNTIFS(Gear!$A$6:$A$14,H7,Gear!$C$6:$C$14,"Defense")=1,COUNTIFS(Gear!$A$6:$A$14,I7,Gear!$C$6:$C$14,"Utility")=1,COUNTIF(Tactics!$A$6:$A$9,J7)=1),"OK","ERROR") -> OK | O7: Сближение, Precision и реализация close window.
A8: build_bear_counter_heavy | B8: Медведь — ответный | C8: bear | D8: bear_earthbreaker | E8: bear_fury_maul | F8: bear_thick_hide | G8: gear_offense_guardbreaker | H8: gear_defense_control_brace | I8: gear_utility_energy_cell | J8: tactic_counter | K8: Normalized 1000 | L8: vs_gorilla | M8: Hypothesis | N8: =IF(AND(D8<>E8,COUNTIFS(Actions!$A$6:$A$29,D8,Actions!$B$6:$B$29,C8,Actions!$D$6:$D$29,"Special")=1,COUNTIFS(Actions!$A$6:$A$29,E8,Actions!$B$6:$B$29,C8,Actions!$D$6:$D$29,"Special")=1,COUNTIFS(Passives!$A$6:$A$11,F8,Passives!$B$6:$B$11,C8)=1,COUNTIFS(Gear!$A$6:$A$14,G8,Gear!$C$6:$C$14,"Offense")=1,COUNTIFS(Gear!$A$6:$A$14,H8,Gear!$C$6:$C$14,"Defense")=1,COUNTIFS(Gear!$A$6:$A$14,I8,Gear!$C$6:$C$14,"Utility")=1,COUNTIF(Tactics!$A$6:$A$9,J8)=1),"OK","ERROR") -> OK | O8: Проверяет, не блокирует ли grab/control comeback полностью.
A9: build_bear_signature | B9: Медведь — ярость | C9: bear | D9: bear_rampage_charge | E9: bear_fury_maul | F9: bear_pressure_fuels_rage | G9: gear_offense_power_wraps | H9: gear_defense_vital_harness | I9: gear_utility_energy_cell | J9: tactic_signature | K9: Normalized 1000 | L9: signature_usage | M9: Hypothesis | N9: =IF(AND(D9<>E9,COUNTIFS(Actions!$A$6:$A$29,D9,Actions!$B$6:$B$29,C9,Actions!$D$6:$D$29,"Special")=1,COUNTIFS(Actions!$A$6:$A$29,E9,Actions!$B$6:$B$29,C9,Actions!$D$6:$D$29,"Special")=1,COUNTIFS(Passives!$A$6:$A$11,F9,Passives!$B$6:$B$11,C9)=1,COUNTIFS(Gear!$A$6:$A$14,G9,Gear!$C$6:$C$14,"Offense")=1,COUNTIFS(Gear!$A$6:$A$14,H9,Gear!$C$6:$C$14,"Defense")=1,COUNTIFS(Gear!$A$6:$A$14,I9,Gear!$C$6:$C$14,"Utility")=1,COUNTIF(Tactics!$A$6:$A$9,J9)=1),"OK","ERROR") -> OK | O9: Измеряет opportunity debt и расход ярости.
A10: build_kangaroo_default | B10: Кенгуру — базовый | C10: kangaroo | D10: kangaroo_flying_kick | E10: kangaroo_tail_counter | F10: kangaroo_never_still | G10: gear_offense_precision_lens | H10: gear_defense_vital_harness | I10: gear_utility_sprint_soles | J10: tactic_position | K10: Normalized 1000 | L10: baseline | M10: Hypothesis | N10: =IF(AND(D10<>E10,COUNTIFS(Actions!$A$6:$A$29,D10,Actions!$B$6:$B$29,C10,Actions!$D$6:$D$29,"Special")=1,COUNTIFS(Actions!$A$6:$A$29,E10,Actions!$B$6:$B$29,C10,Actions!$D$6:$D$29,"Special")=1,COUNTIFS(Passives!$A$6:$A$11,F10,Passives!$B$6:$B$11,C10)=1,COUNTIFS(Gear!$A$6:$A$14,G10,Gear!$C$6:$C$14,"Offense")=1,COUNTIFS(Gear!$A$6:$A$14,H10,Gear!$C$6:$C$14,"Defense")=1,COUNTIFS(Gear!$A$6:$A$14,I10,Gear!$C$6:$C$14,"Utility")=1,COUNTIF(Tactics!$A$6:$A$9,J10)=1),"OK","ERROR") -> OK | O10: Контрольная сборка preferred mid range.
